<!-- NOTE: the joint limits and references have not been set. If using -->
<!-- this to control a real ur5, make sure they align with the values -->
<!-- used in the real arm firmware -->
<!-- Masses and center-of-masses taken from: www.universal-robots.com/
        how-tos-and-faqs/faq/ur-faq/
        parameters-for-calculations-of-kinematics-and-dynamics-45257/ -->
<!-- Principle moments of inertia not provided, set all to 0.1. -->
<!-- Inertia parameters provided at link below, not sure of accuracy so not used:
        http://hades.mech.northwestern.edu/images/4/49/UR5-URDF.pdf -->
<mujoco model="ur5">
    <compiler angle="radian" meshdir="meshes" balanceinertia="true"/>
  <option integrator="implicit" impratio="10" gravity = "0 0 -9.81" timestep="0.001" collision="dynamic"
  cone="pyramidal" noslip_iterations="3"/>
    <default>
        <light castshadow="false" diffuse="1 1 1" />
        <camera fovy="60" />
        <default class="2f85">
          <mesh scale="0.001 0.001 0.001"/>
          <general biastype="affine"/>
          <joint axis="1 0 0"/>
          <default class="driver">
            <joint range="0 0.8" armature="0.005" damping="0.1" solimplimit="0.95 0.99 0.001" solreflimit="0.005 1"/>
          </default>
          <default class="follower">
            <joint range="-0.872664 0.872664" pos="0 -0.018 0.0065" solimplimit="0.95 0.99 0.001" solreflimit="0.005 1"/>
          </default>
          <default class="spring_link">
            <joint range="-0.29670597283 0.8" stiffness="0.05" springref="2.62" damping="0.00125"/>
          </default>
          <default class="coupler">
            <joint range="-1.57 0" solimplimit="0.95 0.99 0.001" solreflimit="0.005 1"/>
          </default>

          <default class="visual1">
            <geom type="mesh" contype="0" conaffinity="0" group="2"/>
          </default>
          <default class="collision1">
            <geom type="mesh" group="3"/>
            <default class="pad_box1">
              <geom mass="0" type="box" pos="0 -0.0026 0.028125" size="0.011 0.004 0.009375" friction="0.7"
                solimp="0.95 0.99 0.001" solref="0.004 1" priority="1" rgba="0.55 0.55 0.55 1"/>
            </default>
            <default class="pad_box2">
              <geom mass="0" type="box" pos="0 -0.0026 0.009375" size="0.011 0.004 0.009375" friction="0.7"
                solimp="0.95 0.99 0.001" solref="0.004 1" priority="1" rgba="0.45 0.45 0.45 1"/>
            </default>
          </default>
        </default>
    </default>

    <custom>
        <numeric name="START_ANGLES" data="0 0 1.57 0 1.57 0"/>
        <numeric name="N_GRIPPER_JOINTS" data="2" />
        <text name="google_id" data="1SjWRUl-D1FZ5fB2cy4jF4X9wTsQ5LWzo"/>
    </custom>

    <asset>
        <!-- arm models -->
        <mesh file="link0.stl"/>
        <mesh file="link1.stl"/>
        <mesh file="link1_cap.stl" />
        <mesh file="link1_connector.stl" />
        <mesh file="link2.stl" />
        <mesh file="link2_tube.stl" />
        <mesh file="link2_cap.stl" />
        <mesh file="link2_connector.stl" />
        <mesh file="link3a.stl" />
        <mesh file="link3a_connector.stl" />
        <mesh file="link3_tube.stl" />
        <mesh file="link3_cap.stl" />
        <mesh file="link3b.stl" />
        <mesh file="link3b_connector.stl" />
        <mesh file="link3b_connector2.stl"/>
        <mesh file="link4.stl" />
        <mesh file="link4_cap.stl" />
        <mesh file="link4_connector.stl" />
        <mesh file="link5.stl" />
        <mesh file="link5_cap.stl" />
        <mesh file="link5_connector.stl" />
        <mesh file="link6.stl" />
        <mesh file="link6_connector.stl" />

        <mesh class="2f85" file="base_mount.stl"/>
        <mesh class="2f85" file="base.stl"/>
        <mesh class="2f85" file="driver.stl"/>
        <mesh class="2f85" file="coupler.stl"/>
        <mesh class="2f85" file="follower.stl"/>
        <mesh class="2f85" file="pad.stl"/>
        <mesh class="2f85" file="silicone_pad.stl"/>
        <mesh class="2f85" file="spring_link.stl"/>

<!--        <texture name="floor_tile" file="meshes/floor_tile.png" width="3000" height="3000" type="2d"/>-->
<!--        <material name="tile" texture="floor_tile" specular="0" shininess="0" reflectance="0" emission="1" />-->
        <texture type="skybox" builtin="gradient" rgb1="0.3 0.5 0.7" rgb2="0 0 0" width="512" height="3072"/>
        <texture type="2d" name="groundplane" builtin="checker" mark="edge" rgb1="0.2 0.3 0.4" rgb2="0.1 0.2 0.3"
      markrgb="0.8 0.8 0.8" width="300" height="300"/>
        <material name="groundplane" texture="groundplane" texuniform="true" texrepeat="5 5" reflectance="0.2"/>
        <material name="silver" specular="1" shininess="0.5" reflectance="1" emission="0.25" rgba="0.82 0.82 0.82 1"/>
        <material name="grey" specular="1" shininess="0.5" reflectance="1" emission="0.1" rgba="0.5 0.5 0.5 1"/>
        <material name="blue" specular="1" shininess="0.5" reflectance="1" emission="0" rgba="0.678 0.847 0.902 1"/>
        <material name="black" specular="1" shininess="0.5" reflectance="1" emission="0" rgba="0.2 0.2 0.2 1"/>
        <material name="metal" rgba="0.58 0.58 0.58 1"/>
        <material name="silicone" rgba="0.1882 0.1882 0.1882 1"/>
        <material name="gray" rgba="0.4627 0.4627 0.4627 1"/>
        <material name="black1" rgba="0.149 0.149 0.149 1"/>

    </asset>

    <worldbody>
<!--        <geom name="floor_grey_tile" pos="0 0 -0.001" size="0.75 0.75 0.05" type="plane" material="tile"/>-->

        <body name="hand" pos="0 0 -0.15" mocap="true">
            <geom type="box" size=".002 .004 .006" rgba="0 .9 0 .5" contype="2" conaffinity="2"/>
        </body>

        <body name="target" pos="0 0 -0.15" mocap="true">
            <geom name="target" type="sphere" size="0.01" rgba=".9 0 0 .5" contype="4" conaffinity="4"/>
        </body>

        <body name="target_orientation" pos="0 0 -0.15" mocap="true">
            <geom type="box" size=".02 .04 .06" rgba=".9 0 0 .5" contype="8" conaffinity="8"/>
        </body>

        <body name="path_planner" pos="0 0 -0.15" mocap="true">
            <geom type="sphere" size="0.05" rgba="0 1 1 0.5" contype="16" conaffinity="16"/>
        </body>

        <body name="path_planner_orientation" pos="0 0 -0.15" mocap="true">
            <geom type="box" size=".02 .04 .06" rgba="0 1 1 .5" contype="16" conaffinity="16"/>
        </body>

        <body name="obstacle" pos="0 0 -0.15" mocap="true">
            <geom type="sphere" size="0.05" rgba="0 0 1 1"/>
        </body>

        <light directional="true" pos="0 0 15" dir="0 0 -1" />
        <geom name="floor" size="0 0 0.05" type="plane" material="groundplane"/>
<!--        <light name="spotlight" mode="targetbodycom" target="link6" pos="0 -1 2"/>-->
        <body name="base_link" pos="0 0 0">
            <geom name="link0" type="mesh" mesh="link0" pos="0 0 0"/>

            <body name="link1" pos="0 0 0.0213">
                <joint name="joint0" axis="0 0 1" pos="0 0 0"/>
                <inertial pos="0 -0.02561 0.00193" mass="3.761" diaginertia="0.1 0.1 0.1"/>
                <geom name="link1_connector" type="mesh" mesh="link1_connector" pos="0 0 0" material="black"
                    conaffinity="32" contype="32"/>
                <geom name="link1" type="mesh" mesh="link1" pos="0 0 0.008" material="grey"/>
                <geom name="link1_cap" type="mesh" mesh="link1_cap" pos="0 0 .1025" material="blue"/>

                <body name="link2" pos="-0.0663 0 0.0679">
                    <joint name="joint1" axis="-1 0 0" pos="0 0 0"/>
                    <inertial pos="-0.04706 0 0.2125" mass="8.058" diaginertia="0.1 0.1 0.1"/>
                    <geom name="link2_connector" type="mesh" mesh="link2_connector" pos="0 0 0" material="black"
                        conaffinity="32" contype="32"/>
                    <geom name="link2" type="mesh" mesh="link2" pos="-0.008 0 0" material="grey"/>
                    <geom name="link2_cap" type="mesh" mesh="link2_cap" pos="-0.1015 0 -0.0025" material="blue"/>
                    <geom name="link2_tube" type="mesh" mesh="link2_tube" pos="-0.0679 0 0.066" material="silver"/>

                    <body name="link3" pos="-0.008 0 0.425">
                        <joint name="joint2" axis="1 0 0" pos="0 0 0"/>
                        <inertial pos="0.0478 0 0.15" mass="2.846" diaginertia="0.1 0.1 0.1"/>
                        <geom name="link3a_connector" type="mesh" mesh="link3a_connector" pos="0 0 0" material="black"
                            conaffinity="32" contype="32"/>
                        <geom name="link3a" type="mesh" mesh="link3a" pos="0.008 0 0" material="grey"/>
                        <geom name="link3_tube" type="mesh" mesh="link3_tube" pos="0.059 0 0.066" material="silver"/>
                        <geom name="link3b_connector" type="mesh" mesh="link3b_connector" pos="0.059 0 0.3418" material="black" />
                        <geom name="link3b_connector2" type="mesh" mesh="link3b_connector2" pos="0.059 0 0.34" material="grey"
                            conaffinity="32" contype="32"/>
                        <geom name="link3b" type="mesh" mesh="link3b" pos="0.059 0 0.347" material="grey"/>
                        <geom name="link3_cap" type="mesh" mesh="link3_cap" pos="0.0837 0 0.392" material="blue"/>

                        <body name="link4" pos="0.0173 0 0.3922">
                            <joint name="joint3" axis="-1 0 0" pos="0 0 0"/>
                            <inertial pos="-0.05796 -0.0018 0" mass="1.37" diaginertia="0.1 0.1 0.1"/>
                            <geom name="link4_connector" type="mesh" mesh="link4_connector" pos="0 0 0" material="black"
                                conaffinity="32" contype="32"/>
                            <geom name="link4" type="mesh" mesh="link4" pos="-0.008 0 0" material="grey"/>
                            <geom name="link4_cap" type="mesh" mesh="link4_cap" pos="-0.05325 0 -0.0247" material="blue"/>

                            <body name="link5" pos="-0.05325 0 0.04165">
                                <joint name="joint4" axis="0 0 1" pos="0 0 0"/>
                                <inertial pos="0.0018 0 0.01634" mass="1.3" diaginertia="0.1 0.1 0.1"/>
                                <geom name="link5_connector" type="mesh" mesh="link5_connector" pos="0 0 0" material="black"
                                    conaffinity="32" contype="32"/>
                                <geom name="link5" type="mesh" mesh="link5" pos="0 0 0.0079" material="grey"/>
                                <geom name="link5_cap" type="mesh" mesh="link5_cap" pos="0.025 0 0.053" material="blue"/>

                                <body name="link6" pos="-0.04165 0 0.05305">
                                    <joint name="joint5" axis="-1 0 0" pos="0 0 0"/>
                                    <inertial pos="-0.038841 0 0" mass="0.365" diaginertia="0.1 0.1 0.1"/>
                                    <geom name="link6_connector" type="mesh" mesh="link6_connector" pos="0 0 0" material="black"
                                        conaffinity="32" contype="32"/>
                                    <geom name="link6" type="mesh" mesh="link6" pos="-0.008 0 0" material="silver"/>
                                    <body name="EE" pos="-0.04 0 0" quat="-1 1 0 0">

<!--                                        <body name="base_mount" pos="-0.1 0 0" childclass="2f85" quat="0 -1 0 1">-->
<!--                                          <geom class="visual1" mesh="base_mount" material="black1"/>-->
<!--                                          <geom class="collision1" mesh="base_mount"/>-->
<!--                                          <body name="gripper_base" pos="0 0 0.0" quat="1 0 0 1">-->
<!--                                            <inertial mass="0.777441" pos="0 -2.70394e-05 0.0354675" quat="1 -0.00152849 0 0"-->
<!--                                              diaginertia="0.000260285 0.000225381 0.000152708"/>-->
<!--                                            <geom class="visual1" mesh="base" material="black1"/>-->
<!--                                            <geom class="collision1" mesh="base"/>-->
<!--                                            <site name="pinch" pos="0 0 0.145" type="sphere" group="5" rgba="0.9 0.9 0.9 1" size="0.005"/>-->
<!--                                            &lt;!&ndash; Right-hand side 4-bar linkage &ndash;&gt;-->
<!--                                            <body name="right_driver" pos="0 0.0306011 0.054904">-->
<!--                                              <inertial mass="0.00899563" pos="2.96931e-12 0.0177547 0.00107314" quat="0.681301 0.732003 0 0"-->
<!--                                                diaginertia="1.72352e-06 1.60906e-06 3.22006e-07"/>-->
<!--                                              <joint name="right_driver_joint" class="driver"/>-->
<!--                                              <geom class="visual1" mesh="driver" material="gray"/>-->
<!--                                              <geom class="collision1" mesh="driver"/>-->
<!--                                              <body name="right_coupler" pos="0 0.0315 -0.0041">-->
<!--                                                <inertial mass="0.0140974" pos="0 0.00301209 0.0232175" quat="0.705636 -0.0455904 0.0455904 0.705636"-->
<!--                                                  diaginertia="4.16206e-06 3.52216e-06 8.88131e-07"/>-->
<!--                                                <joint name="right_coupler_joint" class="coupler"/>-->
<!--                                                <geom class="visual1" mesh="coupler" material="black1"/>-->
<!--                                                <geom class="collision1" mesh="coupler"/>-->
<!--                                              </body>-->
<!--                                            </body>-->
<!--                                            <body name="right_spring_link" pos="0 0.0132 0.0609">-->
<!--                                              <inertial mass="0.0221642" pos="-8.65005e-09 0.0181624 0.0212658" quat="0.663403 -0.244737 0.244737 0.663403"-->
<!--                                                diaginertia="8.96853e-06 6.71733e-06 2.63931e-06"/>-->
<!--                                              <joint name="right_spring_link_joint" class="spring_link"/>-->
<!--                                              <geom class="visual1" mesh="spring_link" material="black1"/>-->
<!--                                              <geom class="collision1" mesh="spring_link"/>-->
<!--                                              <body name="right_follower" pos="0 0.055 0.0375">-->
<!--                                                <inertial mass="0.0125222" pos="0 -0.011046 0.0124786" quat="1 0.1664 0 0"-->
<!--                                                  diaginertia="2.67415e-06 2.4559e-06 6.02031e-07"/>-->
<!--                                                <joint name="right_follower_joint" class="follower"/>-->
<!--                                                <geom class="visual1" mesh="follower" material="black1"/>-->
<!--                                                <geom class="collision1" mesh="follower"/>-->
<!--                                                <body name="right_pad" pos="0 -0.0189 0.01352">-->
<!--                                                  <geom class="pad_box1" name="right_pad1"/>-->
<!--                                                  <geom class="pad_box2" name="right_pad2"/>-->
<!--                                                  <inertial mass="0.0035" pos="0 -0.0025 0.0185" quat="0.707107 0 0 0.707107"-->
<!--                                                    diaginertia="4.73958e-07 3.64583e-07 1.23958e-07"/>-->
<!--                                                  <geom class="visual1" mesh="pad"/>-->
<!--                                                  <body name="right_silicone_pad">-->
<!--                                                    <geom class="collision1" mesh="silicone_pad" friction="1 0.1 0.1"-->
<!--                                                    solimp="0.95 0.99 0.001" solref="0.004 1"/>-->
<!--                                                    <geom class="visual1" mesh="silicone_pad" material="black1" friction="100 0.1 0.1" condim="4"/>-->
<!--                                                  </body>-->
<!--                                                </body>-->
<!--                                              </body>-->
<!--                                            </body>-->
<!--                                            &lt;!&ndash; Left-hand side 4-bar linkage &ndash;&gt;-->
<!--                                            <body name="left_driver" pos="0 -0.0306011 0.054904" quat="0 0 0 1">-->
<!--                                              <inertial mass="0.00899563" pos="0 0.0177547 0.00107314" quat="0.681301 0.732003 0 0"-->
<!--                                                diaginertia="1.72352e-06 1.60906e-06 3.22006e-07"/>-->
<!--                                              <joint name="left_driver_joint" class="driver"/>-->
<!--                                              <geom class="visual1" mesh="driver" material="gray"/>-->
<!--                                              <geom class="collision1" mesh="driver"/>-->
<!--                                              <body name="left_coupler" pos="0 0.0315 -0.0041">-->
<!--                                                <inertial mass="0.0140974" pos="0 0.00301209 0.0232175" quat="0.705636 -0.0455904 0.0455904 0.705636"-->
<!--                                                  diaginertia="4.16206e-06 3.52216e-06 8.88131e-07"/>-->
<!--                                                <joint name="left_coupler_joint" class="coupler"/>-->
<!--                                                <geom class="visual1" mesh="coupler" material="black1"/>-->
<!--                                                <geom class="collision1" mesh="coupler"/>-->
<!--                                              </body>-->
<!--                                            </body>-->
<!--                                            <body name="left_spring_link" pos="0 -0.0132 0.0609" quat="0 0 0 1">-->
<!--                                              <inertial mass="0.0221642" pos="-8.65005e-09 0.0181624 0.0212658" quat="0.663403 -0.244737 0.244737 0.663403"-->
<!--                                                diaginertia="8.96853e-06 6.71733e-06 2.63931e-06"/>-->
<!--                                              <joint name="left_spring_link_joint" class="spring_link"/>-->
<!--                                              <geom class="visual1" mesh="spring_link" material="black1"/>-->
<!--                                              <geom class="collision1" mesh="spring_link"/>-->
<!--                                              <body name="left_follower" pos="0 0.055 0.0375">-->
<!--                                                <inertial mass="0.0125222" pos="0 -0.011046 0.0124786" quat="1 0.1664 0 0"-->
<!--                                                  diaginertia="2.67415e-06 2.4559e-06 6.02031e-07"/>-->
<!--                                                <joint name="left_follower_joint" class="follower"/>-->
<!--                                                <geom class="visual1" mesh="follower" material="black1"/>-->
<!--                                                <geom class="collision1" mesh="follower"/>-->
<!--                                                <body name="left_pad" pos="0 -0.0189 0.01352">-->
<!--                                                  <geom class="pad_box1" name="left_pad1"/>-->
<!--                                                  <geom class="pad_box2" name="left_pad2"/>-->
<!--                                                  <inertial mass="0.0035" pos="0 -0.0025 0.0185" quat="1 0 0 1"-->
<!--                                                    diaginertia="4.73958e-07 3.64583e-07 1.23958e-07"/>-->
<!--                                                  <geom class="visual1" mesh="pad"/>-->
<!--                                                  <body name="left_silicone_pad">-->
<!--                                                    <geom class="collision1" mesh="silicone_pad" friction="1 0.1 0.1"-->
<!--                                                    solimp="0.95 0.99 0.001" solref="0.004 1"/>-->
<!--                                                    <geom class="visual1" mesh="silicone_pad" material="black1" friction="100 0.1 0.1" condim="4"/>-->
<!--                                                  </body>-->
<!--                                                </body>-->
<!--                                              </body>-->
<!--                                            </body>-->
<!--                                          </body>-->
<!--                                        </body>-->

                                    </body>>
                                </body>
                            </body>
                        </body>
                    </body>
                </body>
            </body>
        </body>
<!--        <body name="soft_body" pos="-0.11043447 -0.48708431  0.02">-->
<!--        <freejoint/>-->
<!--            <composite type="box" count="5 5 5" spacing="0.01"-->
<!--            solrefsmooth="0.004 1" solimpsmooth="0.7 0.8 0.1 0.5 6">-->
<!--                <skin rgba="0 1 0 1"/>-->
<!--                <geom type="sphere" size="0.005" rgba="0.8 0.2 0.9 1" mass="0.01"-->
<!--                      friction="0.01 0.01 0.01" solref="0.004 1" solimp="0.95 0.99 0.001"-->
<!--                condim="4"/>-->
<!--            </composite>-->
<!--        </body>-->

    </worldbody>

<!--    <contact>-->
<!--        <exclude body1="gripper_base" body2="left_driver"/>-->
<!--        <exclude body1="gripper_base" body2="right_driver"/>-->
<!--        <exclude body1="gripper_base" body2="left_spring_link"/>-->
<!--        <exclude body1="gripper_base" body2="right_spring_link"/>-->
<!--        <exclude body1="right_coupler" body2="right_follower"/>-->
<!--        <exclude body1="left_coupler" body2="left_follower"/>-->
<!--    </contact>-->

<!--    <tendon>-->
<!--        <fixed name="split">-->
<!--          <joint joint="right_driver_joint" coef="0.5"/>-->
<!--          <joint joint="left_driver_joint" coef="0.5"/>-->
<!--        </fixed>-->
<!--    </tendon>-->

<!--    <equality>-->
<!--        <connect anchor="0 0 0" body1="right_follower" body2="right_coupler" solimp="0.95 0.99 0.001" solref="0.005 1"/>-->
<!--        <connect anchor="0 0 0" body1="left_follower" body2="left_coupler" solimp="0.95 0.99 0.001" solref="0.005 1"/>-->
<!--        <joint joint1="right_driver_joint" joint2="left_driver_joint" polycoef="0 1 0 0 0" solimp="0.95 0.99 0.001"-->
<!--          solref="0.005 1"/>-->
<!--    </equality>-->

    <actuator>
        <motor name="joint0_motor" joint="joint0" ctrllimited="true" ctrlrange="-3.1415 3.1415"/>
        <motor name="joint1_motor" joint="joint1" ctrllimited="true" ctrlrange="-3.1415 3.1415"/>
        <motor name="joint2_motor" joint="joint2" ctrllimited="true" ctrlrange="-3.1415 3.1415"/>
        <motor name="joint3_motor" joint="joint3" ctrllimited="true" ctrlrange="-3.1415 3.1415"/>
        <motor name="joint4_motor" joint="joint4" ctrllimited="true" ctrlrange="-3.1415 3.1415"/>
        <motor name="joint5_motor" joint="joint5" ctrllimited="true" ctrlrange="-3.1415 3.1415"/>
<!--        <general class="2f85" name="fingers_ctrl" tendon="split" forcerange="-5 5" ctrlrange="0 255"-->
<!--  gainprm="0.3137255 0 0" biasprm="0 -100 -10"/>-->
    </actuator>

</mujoco>
